<?xml version="1.0"?>
<robot name="denge1">

<material name="blue">
    <color rgba="0 0 0.8 1"/>
  </material>
<material name="orange">
    <color rgba="0.972 0.746 0.23 1"/>
  </material>
  <material name="black">
    <color rgba="0 0 0 1"/>
  </material>
  <material name="white">
    <color rgba="1 1 1 1"/>
  </material>

  <link name="govde_link">
    <visual>
      <geometry>
        <mesh filename="govde_.stl"/>
      </geometry>
        <origin rpy="0 0 0" xyz="0 0 1.5"/>
        <material name="blue"/>
    </visual>
    <collision>
      <geometry>
        <mesh filename="govde_.stl"/>
      </geometry>
        <origin rpy="0 0 0" xyz="0 0 1.5"/>
    </collision>
    <inertial>
      <mass value="10"/>
      <inertia ixx="1e-3" ixy="0.0" ixz="0.0" iyy="1e-3" iyz="0.0" izz="1e-3"/>
    </inertial>
  </link>

  <link name="tekerlek_link_1">
    <visual>
      <geometry>
        <mesh filename="tekerlek_.stl"/>
      </geometry>
        <origin rpy="0 0 0" xyz="0 0 1.5"/>
        <material name="orange"/>
    </visual>
    <collision>
      <geometry>
        <mesh filename="tekerlek_.stl"/>
      </geometry>
        <origin rpy="0 0 0" xyz="0 0 1.5"/>
    </collision>
    <inertial>
      <mass value="10"/>
      <inertia ixx="1e-3" ixy="0.0" ixz="0.0" iyy="1e-3" iyz="0.0" izz="1e-3"/>
    </inertial>
  </link>

  <joint name="govde_to_tekerlek_1" type="revolute">
    <parent link="govde_link"/>
    <child link="tekerlek_link_1"/>
    <limit effort="1000.0" lower="0.0" upper="0.548" velocity="0.5"/>
    <origin xyz="-0.8 0 0"/>
    <axis xyz="1 0 0 "/>
  </joint>

  <link name="tekerlek_link_2">
    <visual>
      <geometry>
        <mesh filename="tekerlek_.stl"/>
      </geometry>
        <origin rpy="0 0 0" xyz="0 0 1.5"/>
        <material name="white"/>
    </visual>
    <collision>
      <geometry>
        <mesh filename="tekerlek_.stl"/>
      </geometry>
        <origin rpy="0 0 0" xyz="0 0 1.5"/>
    </collision>
    <inertial>
      <mass value="10"/>
      <inertia ixx="1e-3" ixy="0.0" ixz="0.0" iyy="1e-3" iyz="0.0" izz="1e-3"/>
    </inertial>
  </link>

  <joint name="govde_to_tekerlek_2" type="revolute">
    <parent link="govde_link"/>
    <child link="tekerlek_link_2"/>
    <origin xyz="0.8 0 0"/>
    <axis xyz="1 0 0 "/>
    <limit effort="1000.0" lower="0.0" upper="0.548" velocity="0.5"/>
  </joint>

</robot>
